Workbook

Sheet Dashboard
A1: SCARE CORE — Financial Dashboard
A2: Cowsland Farm, South Leverton, Retford
A4: CAPITAL EXPENDITURE SUMMARY
A5: SC CapEx (Scare Core build) | B5: ='SC CapEx £15m'!B27
A6: IC CapEx (Immersive Core build) | B6: ='IC CapEx £15m'!B25
A7: Working Capital Reserve | B7: 2000000
A8: TOTAL INVESTMENT | B8: =SUM(B5:B7)
A10: Funding Source | B10: Private equity investment
A12: OPERATING SUMMARY (from P&L)
B13: Year 1 | C13: Year 2 | D13: Year 3 | E13: Year 4 | F13: Year 5 | G13: Year 6 | H13: Year 7 | I13: Year 8 | J13: Year 9 | K13: Year 10
A14: Total Revenue | B14: ='Annual P&L'!B4 | C14: ='Annual P&L'!C4 | D14: ='Annual P&L'!D4 | E14: ='Annual P&L'!E4 | F14: ='Annual P&L'!F4 | G14: 3282614.4 | H14: 3497496 | I14: 3688432.8 | J14: 3883332.7 | K14: 4071415
A15: Total Operating Costs | B15: ='Annual P&L'!B57 | C15: ='Annual P&L'!C57 | D15: ='Annual P&L'!D57 | E15: ='Annual P&L'!E57 | F15: ='Annual P&L'!F57 | G15: 2414391.5 | H15: 2503412.4 | I15: 2571595.1 | J15: 2642916.6 | K15: 2711499.5
A16: EBITDA | B16: ='Annual P&L'!B58 | C16: ='Annual P&L'!C58 | D16: ='Annual P&L'!D58 | E16: ='Annual P&L'!E58 | F16: ='Annual P&L'!F58 | G16: 868222.86 | H16: 994083.64 | I16: 1116837.6 | J16: 1240416.1 | K16: 1359915.5
A17: EBITDA Margin | B17: ='Annual P&L'!B59 | C17: ='Annual P&L'!C59 | D17: ='Annual P&L'!D59 | E17: ='Annual P&L'!E59 | F17: ='Annual P&L'!F59 | G17: 0.26449128 | H17: 0.28422724 | I17: 0.30279462 | J17: 0.3194205 | K17: 0.33401544
A18: Cumulative EBITDA | B18: ='Annual P&L'!B60 | C18: ='Annual P&L'!C60 | D18: ='Annual P&L'!D60 | E18: ='Annual P&L'!E60 | F18: ='Annual P&L'!F60 | G18: 278444.18 | H18: 1272527.8 | I18: 2389365.4 | J18: 3629781.5 | K18: 4989697
A20: WORKING CAPITAL ANALYSIS
A21: Working Capital Reserve | B21: =B7
A22: Max Cumulative Loss (worst point) | B22: =MIN(B18:F18)
A23: Headroom | B23: =B21+B22
A25: STAFFING SUMMARY
A26: Year-round permanent FTE | B26: 5 | C26: 8 | D26: 10 | E26: 11 | F26: 12 | G26: 13 | H26: 13 | I26: 13 | J26: 13 | K26: 13
A27: Seasonal scare staff (Oct-Dec) | B27: ~130 | C27: ~140 | D27: ~150 | E27: ~160 | F27: ~170 | G27: ~175 | H27: ~180 | I27: ~180 | J27: ~185 | K27: ~185
A28: Off-season programming | B28: None | C28: From Q2 | D28: Full year | E28: Full year | F28: Full year | G28: Full year | H28: Full year | I28: Full year | J28: Full year | K28: Full year

Sheet Balance Sheet
A1: SCARE CORE — Balance Sheet (10-Year)
A2: Asset values at cost less depreciation
B4: Year 1 | C4: Year 2 | D4: Year 3 | E4: Year 4 | F4: Year 5 | G4: Year 6 | H4: Year 7 | I4: Year 8 | J4: Year 9 | K4: Year 10
A5: FIXED ASSETS (at cost)
A6: Land (301 acres, Cowsland Farm) | B6: 6550000 | C6: 6550000 | D6: 6550000 | E6: 6550000 | F6: 6550000 | G6: 6550000 | H6: 6550000 | I6: 6550000 | J6: 6550000 | K6: 6550000
A7: Buildings & conversions (cost) | B7: 7200000 | C7: 7200000 | D7: 7200000 | E7: 7200000 | F7: 7200000 | G7: 7200000 | H7: 7200000 | I7: 7200000 | J7: 7200000 | K7: 7200000
A8: Less: accumulated depreciation (25yr SL) | B8: -288000 | C8: -576000 | D8: -864000 | E8: -1152000 | F8: -1440000 | G8: -1728000 | H8: -2016000 | I8: -2304000 | J8: -2592000 | K8: -2880000
A9: Net buildings | B9: 6912000 | C9: 6624000 | D9: 6336000 | E9: 6048000 | F9: 5760000 | G9: 5472000 | H9: 5184000 | I9: 4896000 | J9: 4608000 | K9: 4320000
A10: Infrastructure (cost) | B10: 1160000 | C10: 1160000 | D10: 1160000 | E10: 1160000 | F10: 1160000 | G10: 1160000 | H10: 1160000 | I10: 1160000 | J10: 1160000 | K10: 1160000
A11: Less: accumulated depreciation (20yr SL) | B11: -58000 | C11: -116000 | D11: -174000 | E11: -232000 | F11: -290000 | G11: -348000 | H11: -406000 | I11: -464000 | J11: -522000 | K11: -580000
A12: Net infrastructure | B12: 1102000 | C12: 1044000 | D12: 986000 | E12: 928000 | F12: 870000 | G12: 812000 | H12: 754000 | I12: 696000 | J12: 638000 | K12: 580000
A13: Creative & technical assets (cost) | B13: 4350000 | C13: 4350000 | D13: 4350000 | E13: 4350000 | F13: 4350000 | G13: 4350000 | H13: 4350000 | I13: 4350000 | J13: 4350000 | K13: 4350000
A14: Less: accumulated depreciation (7yr SL) | B14: -621428.57 | C14: -1242857.1 | D14: -1864285.7 | E14: -2485714.3 | F14: -3107142.9 | G14: -3728571.4 | H14: -4350000 | I14: -4350000 | J14: -4350000 | K14: -4350000
A15: Net creative & technical | B15: 3728571.4 | C15: 3107142.9 | D15: 2485714.3 | E15: 1864285.7 | F15: 1242857.1 | G15: 621428.57 | H15: 0 | I15: 0 | J15: 0 | K15: 0
A16: IP, brand & digital assets (cost) | B16: 2600000 | C16: 2600000 | D16: 2600000 | E16: 2600000 | F16: 2600000 | G16: 2600000 | H16: 2600000 | I16: 2600000 | J16: 2600000 | K16: 2600000
A17: Less: accumulated amortisation (10yr SL) | B17: -260000 | C17: -520000 | D17: -780000 | E17: -1040000 | F17: -1300000 | G17: -1560000 | H17: -1820000 | I17: -2080000 | J17: -2340000 | K17: -2600000
... A24: TOTAL FIXED ASSETS (net book value) | B24: 21182571 | C24: 21233143 | D24: 21033714 | E24: 20704286 | F24: 20244857 | G24: 19655429 | H24: 17766000 | I24: 17668000 | J24: 16270000 | K24: 16042000
A26: CURRENT ASSETS
A27: Cash / working capital reserve | B27: 1291309.2 | C27: 747047.1 | D27: 605575.64 | E27: 811637.05 | F27: 1410221.3 | G27: 2278444.2 | H27: 3272527.8 | I27: 4389365.4 | J27: 5629781.5 | K27: 6989697
A28: Unallocated IC reserve | B28: 4500000 | C28: 3080000 | D28: 1780000 | E28: 480000 | F28: 0 | G28: 0 | H28: 0 | I28: 0 | J28: 0 | K28: 0
A29: TOTAL CURRENT ASSETS | B29: 5791309.2 | C29: 3827047.1 | D29: 2385575.6 | E29: 1291637.1 | F29: 1410221.3 | G29: 2278444.2 | H29: 3272527.8 | I29: 4389365.4 | J29: 5629781.5 | K29: 6989697
A31: TOTAL ASSETS | B31: 26973881 | C31: 25060190 | D31: 23419290 | E31: 21995923 | F31: 21655078 | G31: 21933873 | H31: 21038528 | I31: 22057365 | J31: 21899781 | K31: 23031697
A33: EQUITY & LIABILITIES
A34: Share capital (founder investment) | B34: 32020000 | C34: 32020000 | D34: 32020000 | E34: 32020000 | F34: 32020000 | G34: 32020000 | H34: 32020000 | I34: 32020000 | J34: 32020000 | K34: 32020000
A35: Retained earnings (cumulative P&L) | B35: -1936119.4 | C35: -3849810 | D35: -5490710.1 | E35: -6914077.2 | F35: -8074921.5 | G35: -9096127.3 | H35: -9991472.2 | I35: -10272635 | J35: -10430219 | K35: -10598303
A37: TOTAL EQUITY | B37: 30083881 | C37: 28170190 | D37: 26529290 | E37: 25105923 | F37: 23945078 | G37: 22923873 | H37: 22028528 | I37: 21747365 | J37: 21589781 | K37: 21421697
A39: NET ASSET VALUE | B39: 26973881 | C39: 25060190 | D39: 23419290 | E39: 21995923 | F39: 21655078 | G39: 21933873 | H39: 21038528 | I39: 22057365 | J39: 21899781 | K39: 23031697
A40: (Total Assets = Total Equity, no debt)

Sheet Returns & Valuation
A1: SCARE CORE — Returns & Valuation Analysis
A2: Investment return metrics and enterprise value estimate
A4: INVESTMENT SUMMARY
A5: Total capital deployed | B5: 32020000
A6: Funding structure | B6: 100% equity (zero debt)
A7: Working capital reserve | B7: 2000000
A8: Unallocated IC reserve | B8: 4500000
A10: OPERATIONAL MILESTONES
A11: EBITDA breakeven | B11: Year 4
A12: Cumulative EBITDA turns positive | B12: Year 6
A13: Year 10 EBITDA | B13: 1359915.5
A14: Year 10 EBITDA margin | B14: 0.33401544
A15: Year 10 revenue | B15: 4071415
A16: Cumulative EBITDA (10 years) | B16: 4989697
A17: Total expansion CapEx (10 years) | B17: 9220000
A18: Cumulative free cash flow (EBITDA less expansion) | B18: -4230303
A20: ENTERPRISE VALUE ESTIMATE (Year 10)
A21: Valuation method: EBITDA multiple
A22: EBITDA Multiple | B22: Enterprise Value | C22: Return on Investment | D22: Multiple of Money
A23: 6x EBITDA | B23: 8159492.8 | C23: -0.74517511 | D23: 0.25x
A24: 8x EBITDA | B24: 10879324 | C24: -0.66023349 | D24: 0.34x
A25: 10x EBITDA | B25: 13599155 | C25: -0.57529186 | D25: 0.42x
A26: 12x EBITDA | B26: 16318986 | C26: -0.49035023 | D26: 0.51x
A28: ASSET-BACKED FLOOR VALUE
A29: Net book value of assets (Year 10) | B29: 23031697
A30: Land at current market value (301 acres × £11k) | B30: 3311000
A31: Land with leisure planning (estimated premium) | B31: 7525000
A32: Liquidation floor (land + buildings at 50% of cost) | B32: 10730000
A33: Floor as % of investment | B33: 0.33510306
A35: KEY PERFORMANCE METRICS (10-YEAR)
A36: Metric | B36: Y1 | C36: Y2 | D36: Y3 | E36: Y4 | F36: Y5 | G36: Y6 | H36: Y7 | I36: Y8 | J36: Y9 | K36: Y10
A37: Revenue | B37: 644880 | C37: 1150505.6 | D37: 1810910.4 | E37: 2335296.8 | F37: 2904232.4 | G37: 3282614.4 | H37: 3497496 | I37: 3688432.8 | J37: 3883332.7 | K37: 4071415
A38: EBITDA | B38: -708690.8 | C38: -544262.1 | D38: -141471.46 | E38: 206061.41 | F38: 598584.27 | G38: 868222.86 | H38: 994083.64 | I38: 1116837.6 | J38: 1240416.1 | K38: 1359915.5
A39: EBITDA Margin | B39: -1.0989499 | C39: -0.4730634 | D39: -0.078121736 | E39: 0.088237783 | F39: 0.20610756 | G39: 0.26449128 | H39: 0.28422724 | I39: 0.30279462 | J39: 0.3194205 | K39: 0.33401544
A40: Cumulative EBITDA | B40: -708690.8 | C40: -1252952.9 | D40: -1394424.4 | E40: -1188362.9 | F40: -589778.68 | G40: 278444.18 | H40: 1272527.8 | I40: 2389365.4 | J40: 3629781.5 | K40: 4989697
A41: Net Asset Value | B41: 26973881 | C41: 25060190 | D41: 23419290 | E41: 21995923 | F41: 21655078 | G41: 21933873 | H41: 21038528 | I41: 22057365 | J41: 21899781 | K41: 23031697
A42: Off-season % of revenue | B42: 0 | C42: 0.2082215 | D42: 0.34501983 | E42: 0.40557688 | F42: 0.41248848 | G42: 0.40997791 | H42: 0.41765194 | I42: 0.41631714 | J42: 0.41834961 | K42: 0.41835676

Sheet Cash Flow
A1: QUARTERLY CASH FLOW STATEMENT (10-YEAR)
A2: All figures in GBP
A4: Quarter | B4: Q1 Y1 | C4: Q2 Y1 | D4: Q3 Y1 | E4: Q4 Y1 | F4: Q1 Y2 | G4: Q2 Y2 | H4: Q3 Y2 | I4: Q4 Y2 | J4: Q1 Y3 | K4: Q2 Y3 | L4: Q3 Y3 | M4: Q4 Y3 | N4: Q1 Y4 | O4: Q2 Y4 | P4: Q3 Y4 | Q4: Q4 Y4 | R4: Q1 Y5 | S4: Q2 Y5 | T4: Q3 Y5 | U4: Q4 Y5 | V4: Q1 Y6 | W4: Q2 Y6 | X4: Q3 Y6 | Y4: Q4 Y6 | Z4: Q1 Y7 | AA4: Q2 Y7 | AB4: Q3 Y7 | AC4: Q4 Y7 | AD4: Q1 Y8 | AE4: Q2 Y8 | AF4: Q3 Y8 | AG4: Q4 Y8 | AH4: Q1 Y9 | AI4: Q2 Y9 | AJ4: Q3 Y9 | AK4: Q4 Y9 | AL4: Q1 Y10 | AM4: Q2 Y10 | AN4: Q3 Y10 | AO4: Q4 Y10
A5: CAPITAL EXPENDITURE
A6: SC CapEx (Scare Core build) | B6: 4506000 | C6: 4506000 | D6: 3755000 | E6: 1502000 | F6: 751000 | G6: 0 | H6: 0 | I6: 0 | J6: 0 | K6: 0 | L6: 0 | M6: 0 | N6: 0 | O6: 0 | P6: 0 | Q6: 0 | R6: 0 | S6: 0 | T6: 0 | U6: 0 | V6: 0 | W6: 0 | X6: 0 | Y6: 0 | Z6: 0 | AA6: 0 | AB6: 0 | AC6: 0 | AD6: 0 | AE6: 0 | AF6: 0 | AG6: 0 | AH6: 0 | AI6: 0 | AJ6: 0 | AK6: 0 | AL6: 0 | AM6: 0 | AN6: 0 | AO6: 0
A7: IC CapEx (Immersive Core build) | B7: 6000000 | C7: 4500000 | D7: 3000000 | E7: 1500000 | F7: 0 | G7: 0 | H7: 0 | I7: 0 | J7: 0 | K7: 0 | L7: 0 | M7: 0 | N7: 0 | O7: 0 | P7: 0 | Q7: 0 | R7: 0 | S7: 0 | T7: 0 | U7: 0 | V7: 0 | W7: 0 | X7: 0 | Y7: 0 | Z7: 0 | AA7: 0 | AB7: 0 | AC7: 0 | AD7: 0 | AE7: 0 | AF7: 0 | AG7: 0 | AH7: 0 | AI7: 0 | AJ7: 0 | AK7: 0 | AL7: 0 | AM7: 0 | AN7: 0 | AO7: 0
A8: Annual expansion CapEx | B8: 0 | C8: 0 | D8: 0 | E8: 0 | F8: 300000 | G8: 0 | H8: 0 | I8: 0 | J8: 300000 | K8: 0 | L8: 0 | M8: 0 | N8: 300000 | O8: 0 | P8: 0 | Q8: 0 | R8: 300000 | S8: 0 | T8: 0 | U8: 0 | V8: 1300000 | W8: 0 | X8: 0 | Y8: 0 | Z8: 0 | AA8: 0 | AB8: 0 | AC8: 0 | AD8: 1300000 | AE8: 0 | AF8: 0 | AG8: 0 | AH8: 0 | AI8: 0 | AJ8: 0 | AK8: 0 | AL8: 1300000 | AM8: 0 | AN8: 0 | AO8: 0
A9: Total CapEx | B9: =SUM(B6:B8) | C9: =SUM(C6:C8) | D9: =SUM(D6:D8) | E9: =SUM(E6:E8) | F9: =SUM(F6:F8) | G9: =SUM(G6:G8) | H9: =SUM(H6:H8) | I9: =SUM(I6:I8) | ... U9: =SUM(U6:U8) | V9: 1300000 | W9: 0 | X9: 0 | Y9: 0 | Z9: 0 | AA9: 0 | AB9: 0 | AC9: 0 | AD9: 1300000 | AE9: 0 | AF9: 0 | AG9: 0 | AH9: 0 | AI9: 0 | AJ9: 0 | AK9: 0 | AL9: 1300000 | AM9: 0 | AN9: 0 | AO9: 0
A11: OPERATING REVENUE
A12: Scare season revenue | B12: 0 | C12: 0 | D12: 0 | E12: 644880 | F12: 0 | G12: 0 | H12: 0 | I12: 910946 | J12: 0 | K12: 0 | L12: 0 | M12: 1186110 | N12: 0 | O12: 0 | P12: 0 | Q12: 1388154 | R12: 0 | S12: 0 | T12: 0 | U12: 1706270 | V12: 0 | W12: 0 | X12: 0 | Y12: 1936815 | Z12: 0 | AA12: 0 | AB12: 0 | AC12: 2036760 | AD12: 0 | AE12: 0 | AF12: 0 | AG12: 2152875 | AH12: 0 | AI12: 0 | AJ12: 0 | AK12: 2258742 | AL12: 0 | AM12: 0 | AN12: 0 | AO12: 2368111
A13: Off-season revenue | B13: 0 | C13: 0 | D13: 0 | E13: 0 | F13: 0 | G13: 100000 | H13: 139560 | I13: 0 | J13: 200000 | K13: 210000 | L13: 214800 | M13: 0 | N13: 310000 | O13: 320000 | P13: 317142 | Q13: 0 | R13: 395000 | S13: 400000 | T13: 402962 | U13: 0 | V13: 444113 | W13: 457571 | X13: 444113 | Y13: 0 | Z13: 482042 | AA13: 496650 | AB13: 482042 | AC13: 0 | AD13: 506734 | AE13: 522089 | AF13: 506734 | AG13: 0 | AH13: 536114 | AI13: 552360 | AJ13: 536114 | AK13: 0 | AL13: 562090 | AM13: 579123 | AN13: 562090 | AO13: 0
A14: Total Revenue | B14: =SUM(B12:B13) | C14: =SUM(C12:C13) | D14: =SUM(D12:D13) | E14: =SUM(E12:E13) | F14: =SUM(F12:F13) | G14: =SUM(G12:G13) | H14: =SUM(H12:H13) | I14: =SUM(I12:I13) | ... U14: =SUM(U12:U13) | V14: 444113 | W14: 457571 | X14: 444113 | Y14: 1936815 | Z14: 482042 | AA14: 496650 | AB14: 482042 | AC14: 2036760 | AD14: 506734 | AE14: 522089 | AF14: 506734 | AG14: 2152875 | AH14: 536114 | AI14: 552360 | AJ14: 536114 | AK14: 2258742 | AL14: 562090 | AM14: 579123 | AN14: 562090 | AO14: 2368111
A16: OPERATING COSTS
A17: People costs (quarterly) | B17: 69000 | C17: 69000 | D17: 160000 | E17: 311000 | F17: 120000 | G17: 160000 | H17: 160000 | I17: 360000 | J17: 135000 | K17: 180000 | L17: 180000 | M17: 405000 | N17: 148000 | O17: 198000 | P17: 198000 | Q17: 446000 | R17: 161000 | S17: 215000 | T17: 215000 | U17: 484000 | V17: 213370 | W17: 213370 | X17: 247060 | Y17: 449200 | Z17: 220400 | AA17: 220400 | AB17: 255200 | AC17: 464000 | AD17: 225530 | AE17: 225530 | AF17: 261140 | AG17: 474800 | AH17: 231230 | AI17: 231230 | AJ17: 267740 | AK17: 486800 | AL17: 236550 | AM17: 236550 | AN17: 273900 | AO17: 498000
A18: Site & facilities | B18: 63750 | C18: 63750 | D18: 63750 | E18: 63750 | F18: 70000 | G18: 70000 | H18: 70000 | I18: 70000 | J18: 77500 | K18: 77500 | L18: 77500 | M18: 77500 | N18: 83750 | O18: 83750 | P18: 83750 | Q18: 83750 | R18: 90500 | S18: 90500 | T18: 90500 | U18: 90500 | V18: 86000 | W18: 86000 | X18: 86000 | Y18: 86000 | Z18: 88750 | AA18: 88750 | AB18: 88750 | AC18: 88750 | AD18: 91500 | AE18: 91500 | AF18: 91500 | AG18: 91500 | AH18: 94250 | AI18: 94250 | AJ18: 94250 | AK18: 94250 | AL18: 97250 | AM18: 97250 | AN18: 97250 | AO18: 97250
A19: Insurance | B19: 30000 | C19: 30000 | D19: 30000 | E19: 30000 | F19: 33000 | G19: 33000 | H19: 33000 | I19: 33000 | J19: 36250 | K19: 36250 | L19: 36250 | M19: 36250 | N19: 38750 | O19: 38750 | P19: 38750 | Q19: 38750 | R19: 41500 | S19: 41500 | T19: 41500 | U19: 41500 | V19: 31250 | W19: 31250 | X19: 31250 | Y19: 31250 | Z19: 32500 | AA19: 32500 | AB19: 32500 | AC19: 32500 | AD19: 34000 | AE19: 34000 | AF19: 34000 | AG19: 34000 | AH19: 35250 | AI19: 35250 | AJ19: 35250 | AK19: 35250 | AL19: 36500 | AM19: 36500 | AN19: 36500 | AO19: 36500
A20: Marketing | B20: 16500 | C20: 33000 | D20: 57750 | E20: 57750 | F20: 22000 | G20: 44000 | H20: 66000 | I20: 66000 | J20: 25000 | K20: 50000 | L20: 75000 | M20: 75000 | N20: 27500 | O20: 55000 | P20: 82500 | Q20: 82500 | R20: 30000 | S20: 60000 | T20: 90000 | U20: 90000 | V20: 49281 | W20: 49281 | X20: 95664 | Y20: 95664 | Z20: 51410 | AA20: 51410 | AB20: 99796 | AC20: 99796 | AD20: 53056 | AE20: 53056 | AF20: 102991 | AG20: 102991 | AH20: 54555 | AI20: 54555 | AJ20: 105902 | AK20: 105902 | AL20: 56014 | AM20: 56014 | AN20: 108734 | AO20: 108734
A21: Production & creative | B21: 33750 | C21: 33750 | D21: 33750 | E21: 33750 | F21: 43750 | G21: 43750 | H21: 43750 | I21: 43750 | J21: 57500 | K21: 57500 | L21: 57500 | M21: 57500 | N21: 65000 | O21: 65000 | P21: 65000 | Q21: 65000 | R21: 72500 | S21: 72500 | T21: 72500 | U21: 72500 | V21: 106750 | W21: 106750 | X21: 106750 | Y21: 106750 | Z21: 111500 | AA21: 111500 | AB21: 111500 | AC21: 111500 | AD21: 114250 | AE21: 114250 | AF21: 114250 | AG21: 114250 | AH21: 117500 | AI21: 117500 | AJ21: 117500 | AK21: 117500 | AL21: 120750 | AM21: 120750 | AN21: 120750 | AO21: 120750
A22: Professional services | B22: 17393 | C22: 17393 | D22: 17393 | E22: 17393 | F22: 27296 | G22: 27296 | H22: 27296 | I22: 27296 | J22: 35354 | K22: 35354 | L22: 35354 | M22: 35354 | N22: 36721 | O22: 36721 | P22: 36721 | Q22: 36721 | R22: 36780 | S22: 36780 | T22: 36780 | U22: 36780 | V22: 26375 | W22: 26375 | X22: 26375 | Y22: 26375 | Z22: 27500 | AA22: 27500 | AB22: 27500 | AC22: 27500 | AD22: 28375 | AE22: 28375 | AF22: 28375 | AG22: 28375 | AH22: 29250 | AI22: 29250 | AJ22: 29250 | AK22: 29250 | AL22: 29750 | AM22: 29750 | AN22: 29750 | AO22: 29750
A23: Total Operating Costs | B23: =SUM(B17:B22) | C23: =SUM(C17:C22) | D23: =SUM(D17:D22) | E23: =SUM(E17:E22) | F23: =SUM(F17:F22) | G23: =SUM(G17:G22) | H23: =SUM(H17:H22) | I23: =SUM(I17:I22) | ... U23: =SUM(U17:U22) | V23: 513026 | W23: 513026 | X23: 593099 | Y23: 795239 | Z23: 532060 | AA23: 532060 | AB23: 615246 | AC23: 824046 | AD23: 546711 | AE23: 546711 | AF23: 632256 | AG23: 845916 | AH23: 562035 | AI23: 562035 | AJ23: 649892 | AK23: 868952 | AL23: 576814 | AM23: 576814 | AN23: 666884 | AO23: 890984
A25: NET CASH FLOW
A26: Operating cash flow (Revenue - OpEx) | B26: =B14-B23 | C26: =C14-C23 | D26: =D14-D23 | E26: =E14-E23 | F26: =F14-F23 | G26: =G14-G23 | H26: =H14-H23 | I26: =I14-I23 | ... U26: =U14-U23 | V26: -68913 | W26: -55455 | X26: -148986 | Y26: 1141576 | Z26: -50018 | AA26: -35410 | AB26: -133204 | AC26: 1212714 | AD26: -39977 | AE26: -24622 | AF26: -125522 | AG26: 1306959 | AH26: -25921 | AI26: -9675 | AJ26: -113778 | AK26: 1389790 | AL26: -14724 | AM26: 2309 | AN26: -104794 | AO26: 1477127
A27: Less: CapEx | B27: =-B9 | C27: =-C9 | D27: =-D9 | E27: =-E9 | F27: =-F9 | G27: =-G9 | H27: =-H9 | I27: =-I9 | ... U27: =-U9 | V27: -1300000 | W27: 0 | X27: 0 | Y27: 0 | Z27: 0 | AA27: 0 | AB27: 0 | AC27: 0 | AD27: -1300000 | AE27: 0 | AF27: 0 | AG27: 0 | AH27: 0 | AI27: 0 | AJ27: 0 | AK27: 0 | AL27: -1300000 | AM27: 0 | AN27: 0 | AO27: 0
A28: Net cash flow | B28: =B26+B27 | C28: =C26+C27 | D28: =D26+D27 | E28: =E26+E27 | F28: =F26+F27 | G28: =G26+G27 | H28: =H26+H27 | I28: =I26+I27 | ... U28: =U26+U27 | V28: -1368913 | W28: -55455 | X28: -148986 | Y28: 1141576 | Z28: -50018 | AA28: -35410 | AB28: -133204 | AC28: 1212714 | AD28: -1339977 | AE28: -24622 | AF28: -125522 | AG28: 1306959 | AH28: -25921 | AI28: -9675 | AJ28: -113778 | AK28: 1389790 | AL28: -1314724 | AM28: 2309 | AN28: -104794 | AO28: 1477127
A30: FUNDING & RESERVES
A31: Initial funding (£30M + £2M WC) | B31: 32020000 | C31: 0 | D31: 0 | E31: 0 | F31: 0 | G31: 0 | H31: 0 | I31: 0 | J31: 0 | K31: 0 | L31: 0 | M31: 0 | N31: 0 | O31: 0 | P31: 0 | Q31: 0 | R31: 0 | S31: 0 | T31: 0 | U31: 0 | V31: 0 | W31: 0 | X31: 0 | Y31: 0 | Z31: 0 | AA31: 0 | AB31: 0 | AC31: 0 | AD31: 0 | AE31: 0 | AF31: 0 | AG31: 0 | AH31: 0 | AI31: 0 | AJ31: 0 | AK31: 0 | AL31: 0 | AM31: 0 | AN31: 0 | AO31: 0
A32: Cumulative cash position | B32: =B31+B28 | C32: =B32+C28 | D32: =C32+D28 | E32: =D32+E28 | F32: =E32+F28 | G32: =F32+G28 | H32: =G32+H28 | I32: =H32+I28 | J32: =I32+J28 | ... U32: =T32+U28 | V32: -1166765 | W32: -1222220 | X32: -1371206 | Y32: -229630 | Z32: -279648 | AA32: -315058 | AB32: -448262 | AC32: 764452 | AD32: -575525 | AE32: -600147 | AF32: -725669 | AG32: 581290 | AH32: 555369 | AI32: 545694 | AJ32: 431916 | AK32: 1821706 | AL32: 506982 | AM32: 509291 | AN32: 404497 | AO32: 1881624
A34: Minimum cash position (over 5 years) | B34: =MIN(B32:U32)
A35: Quarter of minimum cash

Sheet Scenario Analysis
A1: SCENARIO ANALYSIS
A2: Base case vs stress scenarios (10-year horizon)
A4: Metric | B4: Downside | C4: Base Case | D4: Upside
A5: ASSUMPTIONS
A6: Scare nights (Y1 / Y5 / Y10) | B6: 20 / 24 / 26 | C6: 24 / 30 / 30 | D6: 26 / 34 / 34
A7: Nightly capacity (Y1 / Y5 / Y10) | B7: 800 / 1,000 / 1,200 | C7: 1,000 / 1,400 / 1,500 | D7: 1,100 / 1,600 / 1,600
A8: Peak utilisation rate | B8: 70% | C8: 85-90% | D8: 92%
A9: Blended ticket price Y1 | B9: £24 | C9: £27 | D9: £30
A10: Annual price increase | B10: 3% | C10: 4-5% | D10: 6-7%
A11: Off-season Y5 revenue | B11: £750k | C11: £1.20M | D11: £1.60M
A12: Off-season Y10 revenue | B12: £1.10M | C12: £1.70M | D12: £2.30M
A13: OpEx growth rate (mature) | B13: 5% | C13: 3-4% | D13: 2-3%
A14: OpEx growth rate | B14: 12% | C14: 10% | D14: 8%
A15: 5-YEAR RESULTS
A16: Year 5 revenue | B16: £1.95M | C16: £2.90M | D16: £3.85M
A17: Year 5 EBITDA | B17: £50k | C17: £599k | D17: £1.15M
A18: EBITDA breakeven year | B18: Year 5 | C18: Year 4 | D18: Year 3
A19: Max cumulative loss (5yr) | B19: £1.85M | C19: £1.39M | D19: £780k
A20: WC headroom at worst point | B20: £150k | C20: £606k | D20: £1.22M
A21: Breakeven year | B21: Not in 5 years | C21: Year 4 | D21: Year 3
A22: 10-YEAR RESULTS | B22: £2.6M | C22: £1.24M | D22: £780k
A23: Year 10 revenue | B23: £2.80M | C23: £4.07M | D23: £5.50M
A24: Year 10 EBITDA | B24: £520k | C24: £1.36M | D24: £2.10M
A25: Year 10 EBITDA margin | B25: 18.6% | C25: 33.4% | D25: 38.2%
A26: Cumulative EBITDA (10yr) | B26: £850k | C26: £4.99M | D26: £9.80M
A27: Cumulative EBITDA turns positive | B27: Year 8 | C27: Year 6 | D27: Year 4
A28: Enterprise value at 8x Y10 EBITDA | B28: £4.2M | C28: £10.9M | D28: £16.8M
A29: SENSITIVITY: PRICING IMPACT
A30: KEY INSIGHT | B30: 5-Year Cumulative EBITDA | C30: Breakeven Year | D30: Headroom
A31: The downside scenario still reaches EBITDA breakeven (Year 5) and cumulative positive (Year 8). Even with 20% lower attendance and pricing, the 10-year cumulative EBITDA is £850k positive. The off-season revenue diversification is the critical differentiator: without it, the downside case would not recover within 10 years. The base case generates nearly £5M cumulative EBITDA and supports an enterprise valuation of £10.9M at 8x — roughly a third of the initial £32M investment recovered through ongoing operations alone, with the balance held in appreciating land and infrastructure assets.
A32: £25 (current off-peak) | B32: (£890k) | C32: Year 5 | D32: £510k
A33: SENSITIVITY: PRICING IMPACT ON 10-YEAR CUMULATIVE EBITDA | B33: (£657k) | C33: Year 4 | D33: £756k
A34: Base ticket price Y1 | B34: 10-Year Cumulative EBITDA | C34: Cumulative Positive Year | D34: Y10 EBITDA
A35: £22 (budget) | B35: £1.8M | C35: Year 9 | D35: £920k
A36: £25 (value) | B36: £3.2M | C36: Year 7 | D36: £1.12M
A37: £27 (base case) | B37: £4.99M | C37: Year 6 | D37: £1.36M
A38: £30 (premium) | B38: £7.1M | C38: Year 5 | D38: £1.65M
A39: £35 (ultra-premium) | B39: £10.8M | C39: Year 4 | D39: £2.15M

Sheet SC CapEx £15m
A1: SCARE CORE — Capital Expenditure Budget
A2: SC CapEx allocation from £30M total investment
B3: Amount
A4: LAND & ACQUISITION
A5: Cowsland Farm purchase (301 acres) | B5: 6550000
A6: Legal, survey & stamp duty | B6: 350000
A7: CONSTRUCTION & CONVERSION
A8: 6x maze barn conversions (scenic, structural, M&E) | B8: 3200000
A9: Courtyard (The Yard) construction | B9: 400000
A10: Theatre Barn conversion | B10: 500000
A11: HQ / admin building fit-out | B11: 200000
A12: INFRASTRUCTURE
A13: Car park (800 spaces) + access road | B13: 350000
A14: Utilities (electric, gas, water, broadband) | B14: 300000
A15: Drainage & sewerage | B15: 180000
A16: Pedestrian bridge (permanent or seasonal hire) | B16: 150000
A17: DDA crossing & traffic signals | B17: 60000
A18: Fencing, security & CCTV | B18: 120000
A19: CREATIVE & TECHNICAL
A20: Scenic design & fabrication (all 6 mazes) | B20: 700000
A21: Lighting, sound & AV systems | B21: 350000
A22: SFX, fog, scent, animatronics | B22: 250000
A23: Costume & prop initial stock | B23: 150000
A24: Freelance designers & scenic artists (build phase) | B24: 300000
A25: CONTINGENCY
A26: Contingency (approx 15%) | B26: 910000
A27: TOTAL SC CapEx | B27: =B5+B6+B8+B9+B10+B11+B13+B14+B15+B16+B17+B18+B20+B21+B22+B23+B24+B26

Sheet IC CapEx £15m
A1: IMMERSIVE CORE — Capital Expenditure Budget
A2: IC CapEx allocation from £30M total investment
B3: Amount
A4: IMMERSIVE EXPERIENCES
A5: Immersive theatre venue development | B5: 2000000
A6: Escape room design & build (3 rooms) | B6: 400000
A7: Immersive dining experience build | B7: 500000
A8: Interactive technology & projection | B8: 800000
A9: CONTENT & CREATIVE
A10: Original IP development | B10: 1500000
A11: Show design & production | B11: 1200000
A12: Costume, props & scenic for IC | B12: 600000
A13: TECHNOLOGY & INFRASTRUCTURE
A14: Booking & ticketing platform | B14: 200000
A15: Website & digital experience | B15: 150000
A16: CRM & marketing automation | B16: 100000
A17: BUSINESS DEVELOPMENT
A18: Brand development & launch | B18: 500000
A19: Market research & feasibility | B19: 150000
A20: Legal & corporate structure | B20: 200000
A21: CONTINGENCY
A22: Contingency (approx 15%) | B22: 2200000
A23: RESERVE
A24: Unallocated reserve | B24: 4500000
A25: TOTAL IC CapEx | B25: =B5+B6+B7+B8+B10+B11+B12+B14+B15+B16+B18+B19+B20+B22+B24

Sheet Off-Season Detail
A1: OFF-SEASON REVENUE DETAIL
A2: Theatre Barn, Escape Rooms & Private Events breakdown
B4: Year 1 | C4: Year 2 | D4: Year 3 | E4: Year 4 | F4: Year 5 | G4: Year 6 | H4: Year 7 | I4: Year 8 | J4: Year 9 | K4: Year 10
A5: IMMERSIVE THEATRE (Theatre Barn)
A6: Operating weeks | B6: 0 | C6: 20 | D6: 32 | E6: 36 | F6: 38 | G6: 40 | H6: 40 | I6: 40 | J6: 40 | K6: 40
A7: Performances per week | B7: 0 | C7: 3 | D7: 3 | E7: 4 | F7: 4 | G7: 4 | H7: 4 | I7: 4 | J7: 4 | K7: 4
A8: Seat capacity | B8: 0 | C8: 120 | D8: 140 | E8: 150 | F8: 150 | G8: 150 | H8: 150 | I8: 150 | J8: 150 | K8: 150
A9: Average occupancy | B9: 0 | C9: 0.6 | D9: 0.7 | E9: 0.7 | F9: 0.75 | G9: 0.78 | H9: 0.8 | I9: 0.82 | J9: 0.82 | K9: 0.82
A10: Average ticket price | B10: 0 | C10: 28 | D10: 30 | E10: 32 | F10: 35 | G10: 36 | H10: 38 | I10: 39 | J10: 40 | K10: 42
A11: Total theatre revenue | B11: =B6*B7*B8*B9*B10 | C11: =C6*C7*C8*C9*C10 | D11: =D6*D7*D8*D9*D10 | E11: =E6*E7*E8*E9*E10 | F11: =F6*F7*F8*F9*F10 | G11: 673920 | H11: 729600 | I11: 767520 | J11: 787200 | K11: 826560
A13: ESCAPE ROOMS (Retrofitted Mazes)
A14: Mazes converted for escape use | B14: 0 | C14: 2 | D14: 3 | E14: 4 | F14: 4 | G14: 4 | H14: 4 | I14: 4 | J14: 4 | K14: 4
A15: Operating weeks | B15: 0 | C15: 24 | D15: 40 | E15: 44 | F15: 48 | G15: 48 | H15: 48 | I15: 48 | J15: 48 | K15: 48
A16: Sessions per maze per week | B16: 0 | C16: 10 | D16: 12 | E16: 12 | F16: 14 | G16: 14 | H16: 14 | I16: 14 | J16: 14 | K16: 14
A17: Group size (avg) | B17: 0 | C17: 5 | D17: 6 | E17: 6 | F17: 6 | G17: 6 | H17: 6 | I17: 6 | J17: 6 | K17: 6
A18: Booking rate (utilisation) | B18: 0 | C18: 0.5 | D18: 0.55 | E18: 0.6 | F18: 0.65 | G18: 0.68 | H18: 0.7 | I18: 0.72 | J18: 0.73 | K18: 0.75
A19: Price per person | B19: 0 | C19: 28 | D19: 30 | E19: 32 | F19: 32 | G19: 34 | H19: 35 | I19: 36 | J19: 38 | K19: 39
A20: Total escape room revenue | B20: =B14*B15*B16*B17*B18*B19 | C20: =C14*C15*C16*C17*C18*C19 | D20: =D14*D15*D16*D17*D18*D19 | E20: =E14*E15*E16*E17*E18*E19 | F20: =F14*F15*F16*F17*F18*F19 | G20: 372879.36 | H20: 395136 | I20: 418037.76 | J20: 447390.72 | K20: 471744
A22: PRIVATE EVENTS & CORPORATE HIRE
A23: Events per year | B23: 0 | C23: 10 | D23: 20 | E23: 22 | F23: 24 | G23: 26 | H23: 28 | I23: 28 | J23: 30 | K23: 30
A24: Average revenue per event | B24: 0 | C24: 8500 | D24: 10000 | E24: 10000 | F24: 11000 | G24: 11500 | H24: 12000 | I24: 12500 | J24: 13000 | K24: 13500
A25: Total events revenue | B25: =B23*B24 | C25: =C23*C24 | D25: =D23*D24 | E25: =E23*E24 | F25: =F23*F24 | G25: 299000 | H25: 336000 | I25: 350000 | J25: 390000 | K25: 405000
A27: TOTAL OFF-SEASON REVENUE | B27: =B11+B20+B25 | C27: =C11+C20+C25 | D27: =D11+D20+D25 | E27: =E11+E20+E25 | F27: =F11+F20+F25 | G27: 1345799.4 | H27: 1460736 | I27: 1535557.8 | J27: 1624590.7 | K27: 1703304
A28: Revenue Model off-season total (cross-check) | B28: ='Revenue Model'!B35 | C28: ='Revenue Model'!C35 | D28: ='Revenue Model'!D35 | E28: ='Revenue Model'!E35 | F28: ='Revenue Model'!F35 | G28: 1345799.4 | H28: 1460736 | I28: 1535557.8 | J28: 1624590.7 | K28: 1703304
A29: Variance | B29: =B27-B28 | C29: =C27-C28 | D29: =D27-D28 | E29: =E27-E28 | F29: =F27-F28 | G29: 0 | H29: 0 | I29: 0 | J29: 0 | K29: 0
A31: NOTES
A32: Year 1: No off-season revenue. Site is under construction. Theatre Barn build completes late Y1.
A33: Year 2: Theatre Barn opens Q2. 2 mazes retrofitted for escape rooms over winter. Partial year operations.
A34: Year 3: Full year operations. Third maze converted. Theatre runs 30 weeks with 3 shows/week.
A35: Year 4: Fourth maze converted. Theatre capacity expanded to 150 (flexible seating). Events programme grows.
A36: Year 5: Mature operations. 4 shows/week in theatre. 14 escape sessions/maze/week. 24 private events/year.
A37: Theatre Barn: 3,000 sq ft flexible performance space. Monthly residencies Jan-Sep.
A38: Escape rooms: Existing maze structures retrofitted with puzzle/narrative layers. No new builds required.
A39: Private events: Corporate team-building, birthday parties, themed dinners, charity events, film location hire.

Sheet Revenue Model
A1: SCARE CORE — Revenue Model (10-Year)
A2: Premium pricing — Cowsland Farm, South Leverton
B3: Year 1 | C3: Year 2 | D3: Year 3 | E3: Year 4 | F3: Year 5 | G3: Year 6 | H3: Year 7 | I3: Year 8 | J3: Year 9 | K3: Year 10
A4: SCARE SEASON CAPACITY
A5: Max nightly capacity | B5: 1000 | C5: 1100 | D5: 1200 | E5: 1300 | F5: 1400 | G5: 1500 | H5: 1500 | I5: 1500 | J5: 1500 | K5: 1500
A6: Off-peak nights (weekday) | B6: 6 | C6: 6 | D6: 8 | E6: 8 | F6: 10 | G6: 10 | H6: 10 | I6: 10 | J6: 10 | K6: 10
A7: Peak nights (weekend/half-term) | B7: 10 | C7: 12 | D7: 12 | E7: 12 | F7: 12 | G7: 12 | H7: 12 | I7: 12 | J7: 12 | K7: 12
A8: Super-peak nights (Halloween week) | B8: 8 | C8: 8 | D8: 8 | E8: 8 | F8: 8 | G8: 8 | H8: 8 | I8: 8 | J8: 8 | K8: 8
A9: Total operating nights | B9: =B6+B7+B8 | C9: =C6+C7+C8 | D9: =D6+D7+D8 | E9: =E6+E7+E8 | F9: =F6+F7+F8 | G9: 30 | H9: 30 | I9: 30 | J9: 30 | K9: 30
A10: Average utilisation | B10: 0.65 | C10: 0.72 | D10: 0.78 | E10: 0.82 | F10: 0.85 | G10: 0.87 | H10: 0.88 | I10: 0.89 | J10: 0.9 | K10: 0.9
A12: TICKET PRICING (Premium)
A13: Off-peak ticket price | B13: 25 | C13: 27 | D13: 29 | E13: 30 | F13: 32 | G13: 33 | H13: 34 | I13: 36 | J13: 37 | K13: 39
A14: Peak ticket price | B14: 35 | C14: 38 | D14: 40 | E14: 42 | F14: 44 | G14: 46 | H14: 48 | I14: 50 | J14: 52 | K14: 54
A15: Super-peak ticket price | B15: 45 | C15: 48 | D15: 50 | E15: 50 | F15: 52 | G15: 54 | H15: 56 | I15: 58 | J15: 60 | K15: 63
A17: SCARE REVENUE
A18: Off-peak guests | B18: =B5*B6*B10 | C18: =C5*C6*C10 | D18: =D5*D6*D10 | E18: =E5*E6*E10 | F18: =F5*F6*F10 | G18: 13050 | H18: 13200 | I18: 13350 | J18: 13500 | K18: 13500
A19: Peak guests | B19: =B5*B7*B10 | C19: =C5*C7*C10 | D19: =D5*D7*D10 | E19: =E5*E7*E10 | F19: =F5*F7*F10 | G19: 15660 | H19: 15840 | I19: 16020 | J19: 16200 | K19: 16200
A20: Super-peak guests | B20: =B5*B8*B10 | C20: =C5*C8*C10 | D20: =D5*D8*D10 | E20: =E5*E8*E10 | F20: =F5*F8*F10 | G20: 10440 | H20: 10560 | I20: 10680 | J20: 10800 | K20: 10800
A21: Total season guests | B21: =B18+B19+B20 | C21: =C18+C19+C20 | D21: =D18+D19+D20 | E21: =E18+E19+E20 | F21: =F18+F19+F20 | G21: 39150 | H21: 39600 | I21: 40050 | J21: 40500 | K21: 40500
A23: Ticket revenue | B23: =(B18*B13)+(B19*B14)+(B20*B15) | C23: =(C18*C13)+(C19*C14)+(C20*C15) | D23: =(D18*D13)+(D19*D14)+(D20*D15) | E23: =(E18*E13)+(E19*E14)+(E20*E15) | F23: =(F18*F13)+(F19*F14)+(F20*F15) | G23: 1714770 | H23: 1800480 | I23: 1901040 | J23: 1989900 | K23: 2081700
A24: Merchandise (£4/guest, 35% attach) | B24: =B21*4*0.35 | C24: =C21*4*0.35 | D24: =D21*4*0.35 | E24: =E21*4*0.35 | F24: =F21*4*0.35 | G24: 54810 | H24: 55440 | I24: 56070 | J24: 56700 | K24: 56700
A25: Hospitality (£3/guest, 30% attach) | B25: =B21*3*0.3 | C25: =C21*3*0.3 | D25: =D21*3*0.3 | E25: =E21*3*0.3 | F25: =F21*3*0.3 | G25: 35235 | H25: 35640 | I25: 36045 | J25: 36450 | K25: 36450
A26: VIP / fast-track passes | B26: 50000 | C26: 70000 | D26: 85000 | E26: 100000 | F26: 120000 | G26: 132000 | H26: 145200 | I26: 159720 | J26: 175692 | K26: 193261
A27: Total scare revenue | B27: =SUM(B23:B26) | C27: =SUM(C23:C26) | D27: =SUM(D23:D26) | E27: =SUM(E23:E26) | F27: =SUM(F23:F26) | G27: 1936815 | H27: 2036760 | I27: 2152875 | J27: 2258742 | K27: 2368111
A29: OFF-SEASON REVENUE (Jan-Sep)
A30: Note: No off-season in Y1 (building site). Y2 partial (from Q2).
A31: Theatre / immersive shows | B31: ='Off-Season Detail'!B11 | C31: ='Off-Season Detail'!C11 | D31: ='Off-Season Detail'!D11 | E31: ='Off-Season Detail'!E11 | F31: ='Off-Season Detail'!F11 | G31: 673920 | H31: 729600 | I31: 767520 | J31: 787200 | K31: 826560
A32: Escape rooms (maze barn retrofit) | B32: ='Off-Season Detail'!B20 | C32: ='Off-Season Detail'!C20 | D32: ='Off-Season Detail'!D20 | E32: ='Off-Season Detail'!E20 | F32: ='Off-Season Detail'!F20 | G32: 372879.36 | H32: 395136 | I32: 418037.76 | J32: 447390.72 | K32: 471744
A33: Venue hire (corporate/private) | B33: ='Off-Season Detail'!B25 | C33: ='Off-Season Detail'!C25 | D33: ='Off-Season Detail'!D25 | E33: ='Off-Season Detail'!E25 | F33: ='Off-Season Detail'!F25 | G33: 299000 | H33: 336000 | I33: 350000 | J33: 390000 | K33: 405000
A34: Workshops & educational | B34: 0 | C34: 0 | D34: 0 | E34: 0 | F34: 0 | G34: 0 | H34: 0 | I34: 0 | J34: 0 | K34: 0
A35: Total off-season revenue | B35: =SUM(B31:B34) | C35: =SUM(C31:C34) | D35: =SUM(D31:D34) | E35: =SUM(E31:E34) | F35: =SUM(F31:F34) | G35: 1345799.4 | H35: 1460736 | I35: 1535557.8 | J35: 1624590.7 | K35: 1703304
A37: TOTAL REVENUE
A38: TOTAL ANNUAL REVENUE | B38: =B27+B35 | C38: =C27+C35 | D38: =D27+D35 | E38: =E27+E35 | F38: =F27+F35 | G38: 3282614.4 | H38: 3497496 | I38: 3688432.8 | J38: 3883332.7 | K38: 4071415
A40: CONSOLIDATED TICKET PRICING MATRIX
A41: Single source of truth for all pricing assumptions
B42: Year 1 | C42: Year 2 | D42: Year 3 | E42: Year 4 | F42: Year 5 | G42: Year 6 | H42: Year 7 | I42: Year 8 | J42: Year 9 | K42: Year 10
A43: Off-peak (weekday) | B43: 25 | C43: 27 | D43: 29 | E43: 30 | F43: 32 | G43: 33 | H43: 34 | I43: 36 | J43: 37 | K43: 39
A44: Peak (weekend/half-term) | B44: 35 | C44: 38 | D44: 40 | E44: 42 | F44: 44 | G44: 46 | H44: 48 | I44: 50 | J44: 52 | K44: 54
A45: Super-peak (Halloween week) | B45: 45 | C45: 48 | D45: 50 | E45: 50 | F45: 52 | G45: 54 | H45: 56 | I45: 58 | J45: 60 | K45: 63
A46: Blended average | B46: 0 | C46: 0 | D46: 0 | E46: 0 | F46: 0 | G46: 43.8 | H46: 45.47 | I46: 47.47 | J46: 49.13 | K46: 51.4
...

Sheet Annual P&L
A1: SCARE CORE — Annual Profit & Loss (10-Year)
A2: Operating costs and profitability projection
B3: Year 1 | C3: Year 2 | D3: Year 3 | E3: Year 4 | F3: Year 5 | G3: Year 6 | H3: Year 7 | I3: Year 8 | J3: Year 9 | K3: Year 10
A4: TOTAL REVENUE | B4: ='Revenue Model'!B38 | C4: ='Revenue Model'!C38 | D4: ='Revenue Model'!D38 | E4: ='Revenue Model'!E38 | F4: ='Revenue Model'!F38 | G4: 3282614.4 | H4: 3497496 | I4: 3688432.8 | J4: 3883332.7 | K4: 4071415
A6: PEOPLE COSTS
A7: Year-round permanent team (see staffing plan) | B7: 276000 | C7: 430000 | D7: 505000 | E7: 560000 | F7: 610000 | G7: 640000 | H7: 660000 | I7: 680000 | J7: 700000 | K7: 720000
A8: Payroll bureau / outsourced HR | B8: 8000 | C8: 10000 | D8: 0 | E8: 0 | F8: 0 | G8: 0 | H8: 0 | I8: 0 | J8: 0 | K8: 0
A9: Note: HR coordinator hired in-house from Y3
A10: Seasonal performers (scare actors, Oct-Dec) | B10: 220000 | C10: 240000 | D10: 260000 | E10: 280000 | F10: 300000 | G10: 310000 | H10: 320000 | I10: 325000 | J10: 330000 | K10: 335000
A11: Seasonal support staff (bar, merch, parking) | B11: 80000 | C11: 90000 | D11: 100000 | E11: 110000 | F11: 120000 | G11: 125000 | H11: 130000 | I11: 132000 | J11: 135000 | K11: 138000
A12: Staff training & development | B12: 25000 | C12: 30000 | D12: 35000 | E12: 40000 | F12: 45000 | G12: 48000 | H12: 50000 | I12: 50000 | J12: 52000 | K12: 52000
A13: Subtotal people costs | B13: =SUM(B7:B8,B10:B12) | C13: =SUM(C7:C8,C10:C12) | D13: =SUM(D7:D8,D10:D12) | E13: =SUM(E7:E8,E10:E12) | F13: =SUM(F7:F8,F10:F12) | G13: 1123000 | H13: 1160000 | I13: 1187000 | J13: 1217000 | K13: 1245000
A15: SITE & FACILITIES
A16: Utilities (electric, gas, water) | B16: 85000 | C16: 88000 | D16: 92000 | E16: 96000 | F16: 100000 | G16: 103000 | H16: 106000 | I16: 109000 | J16: 112000 | K16: 116000
A17: Business rates | B17: 45000 | C17: 47000 | D17: 49000 | E17: 51000 | F17: 53000 | G17: 55000 | H17: 57000 | I17: 59000 | J17: 61000 | K17: 63000
A18: Site maintenance & repairs | B18: 55000 | C18: 58000 | D18: 62000 | E18: 66000 | F18: 70000 | G18: 73000 | H18: 76000 | I18: 79000 | J18: 82000 | K18: 85000
A19: Waste management | B19: 15000 | C19: 16000 | D19: 17000 | E19: 18000 | F19: 19000 | G19: 20000 | H19: 21000 | I19: 21000 | J19: 22000 | K19: 22000
A20: Pedestrian bridge (seasonal hire) | B20: 25000 | C20: 27000 | D20: 28000 | E20: 29000 | F20: 30000 | G20: 31000 | H20: 32000 | I20: 33000 | J20: 34000 | K20: 35000
A21: DDA crossing & traffic signals (seasonal) | B21: 18000 | C21: 19000 | D21: 20000 | E21: 20000 | F21: 21000 | G21: 22000 | H21: 22000 | I21: 23000 | J21: 23000 | K21: 24000
A22: Grounds maintenance (301 acres) | B22: 30000 | C22: 32000 | D22: 34000 | E22: 36000 | F22: 38000 | G22: 40000 | H22: 41000 | I22: 42000 | J22: 43000 | K22: 44000
A23: Subtotal site & facilities | B23: =SUM(B16:B22) | C23: =SUM(C16:C22) | D23: =SUM(D16:D22) | E23: =SUM(E16:E22) | F23: =SUM(F16:F22) | G23: 344000 | H23: 355000 | I23: 366000 | J23: 377000 | K23: 389000
A25: INSURANCE
A26: Public liability (£10m+) | B26: 45000 | C26: 48000 | D26: 51000 | E26: 54000 | F26: 57000 | G26: 59000 | H26: 61000 | I26: 63000 | J26: 65000 | K26: 67000
A27: Employers liability | B27: 8000 | C27: 9000 | D27: 10000 | E27: 11000 | F27: 12000 | G27: 13000 | H27: 13000 | I27: 14000 | J27: 14000 | K27: 15000
A28: Property & contents | B28: 25000 | C28: 27000 | D28: 29000 | E28: 31000 | F28: 33000 | G28: 35000 | H28: 37000 | I28: 39000 | J28: 41000 | K28: 43000
A29: Professional indemnity | B29: 8000 | C29: 8500 | D29: 9000 | E29: 9500 | F29: 10000 | G29: 10500 | H29: 11000 | I29: 11500 | J29: 12000 | K29: 12000
A30: Cyber & data protection | B30: 5000 | C30: 5500 | D30: 6000 | E30: 6500 | F30: 7000 | G30: 7500 | H30: 8000 | I30: 8500 | J30: 9000 | K30: 9000
A31: Subtotal insurance | B31: =SUM(B26:B30) | C31: =SUM(C26:C30) | D31: =SUM(D26:D30) | E31: =SUM(E26:E30) | F31: =SUM(F26:F30) | G31: 125000 | H31: 130000 | I31: 136000 | J31: 141000 | K31: 146000
A33: MARKETING & SALES
A34: Digital marketing (social, PPC, influencer) | B34: 100000 | C34: 120000 | D34: 135000 | E34: 145000 | F34: 155000 | G34: 160000 | H34: 165000 | I34: 168000 | J34: 170000 | K34: 172000
A35: PR & earned media | B35: 25000 | C35: 20000 | D35: 18000 | E35: 15000 | F35: 12000 | G35: 10000 | H35: 10000 | I35: 10000 | J35: 10000 | K35: 10000
A36: Print & outdoor advertising | B36: 10000 | C36: 8000 | D36: 7000 | E36: 6000 | F36: 5000 | G36: 5000 | H36: 5000 | I36: 5000 | J36: 5000 | K36: 5000
A37: Ticketing platform fees (3.5%) | B37: =B4*0.035 | C37: =C4*0.035 | D37: =D4*0.035 | E37: =E4*0.035 | F37: =F4*0.035 | G37: 114891.5 | H37: 122412.36 | I37: 129095.15 | J37: 135916.65 | K37: 142499.53
A38: Subtotal marketing & sales | B38: =SUM(B34:B37) | C38: =SUM(C34:C37) | D38: =SUM(D34:D37) | E38: =SUM(E34:E37) | F38: =SUM(F34:F37) | G38: 289891.5 | H38: 302412.36 | I38: 312095.15 | J38: 320916.65 | K38: 329499.53
A40: PRODUCTION & CREATIVE
A41: Costume & prop refresh (annual scare season) | B41: 70000 | C41: 80000 | D41: 90000 | E41: 100000 | F41: 110000 | G41: 115000 | H41: 120000 | I41: 122000 | J41: 125000 | K41: 128000
A42: Set maintenance & updates | B42: 35000 | C42: 40000 | D42: 45000 | E42: 50000 | F42: 55000 | G42: 58000 | H42: 60000 | I42: 62000 | J42: 65000 | K42: 68000
A43: Tech maintenance (AV, lighting, SFX) | B43: 30000 | C43: 33000 | D43: 36000 | E43: 39000 | F43: 42000 | G43: 44000 | H43: 46000 | I43: 48000 | J43: 50000 | K43: 52000
A44: Theatre / off-season production costs | B44: 0 | C44: 80000 | D44: 160000 | E44: 180000 | F44: 200000 | G44: 210000 | H44: 220000 | I44: 225000 | J44: 230000 | K44: 235000
A45: Note: £0 in Y1 (no off-season programming)
...
